[Sat Sep 19 17:18:11.194455 2020] [wsgi:error] [pid 23485] [remote 91.12.161.88:39034] mod_wsgi (pid=23485): Failed to exec Python script file '/home/mastergoal_project/config/wsgi.py'.
[Sat Sep 19 17:18:11.194536 2020] [wsgi:error] [pid 23485] [remote 91.12.161.88:39034] mod_wsgi (pid=23485): Exception occurred processing WSGI script '/home/mastergoal_project/config/wsgi.py'.
[Sat Sep 19 17:18:11.196408 2020] [wsgi:error] [pid 23485] [remote 91.12.161.88:39034] Traceback (most recent call last):
[Sat Sep 19 17:18:11.196448 2020] [wsgi:error] [pid 23485] [remote 91.12.161.88:39034]   File "/usr/lib/python3.7/logging/config.py", line 563, in configure
[Sat Sep 19 17:18:11.196455 2020] [wsgi:error] [pid 23485] [remote 91.12.161.88:39034]     handler = self.configure_handler(handlers[name])
[Sat Sep 19 17:18:11.196461 2020] [wsgi:error] [pid 23485] [remote 91.12.161.88:39034]   File "/usr/lib/python3.7/logging/config.py", line 736, in configure_handler
[Sat Sep 19 17:18:11.196465 2020] [wsgi:error] [pid 23485] [remote 91.12.161.88:39034]     result = factory(**kwargs)
[Sat Sep 19 17:18:11.196471 2020] [wsgi:error] [pid 23485] [remote 91.12.161.88:39034]   File "/usr/lib/python3.7/logging/__init__.py", line 1087, in __init__
[Sat Sep 19 17:18:11.196477 2020] [wsgi:error] [pid 23485] [remote 91.12.161.88:39034]     StreamHandler.__init__(self, self._open())
[Sat Sep 19 17:18:11.196487 2020] [wsgi:error] [pid 23485] [remote 91.12.161.88:39034]   File "/usr/lib/python3.7/logging/__init__.py", line 1116, in _open
[Sat Sep 19 17:18:11.196492 2020] [wsgi:error] [pid 23485] [remote 91.12.161.88:39034]     return open(self.baseFilename, self.mode, encoding=self.encoding)
[Sat Sep 19 17:18:11.196519 2020] [wsgi:error] [pid 23485] [remote 91.12.161.88:39034] FileNotFoundError: [Errno 2] No such file or directory: '/home/mastergoal_project/logs/critical.log'
[Sat Sep 19 17:18:11.196528 2020] [wsgi:error] [pid 23485] [remote 91.12.161.88:39034] 
[Sat Sep 19 17:18:11.196532 2020] [wsgi:error] [pid 23485] [remote 91.12.161.88:39034] The above exception was the direct cause of the following exception:
[Sat Sep 19 17:18:11.196536 2020] [wsgi:error] [pid 23485] [remote 91.12.161.88:39034] 
[Sat Sep 19 17:18:11.196541 2020] [wsgi:error] [pid 23485] [remote 91.12.161.88:39034] Traceback (most recent call last):
[Sat Sep 19 17:18:11.196567 2020] [wsgi:error] [pid 23485] [remote 91.12.161.88:39034]   File "/home/mastergoal_project/config/wsgi.py", line 16, in <module>
[Sat Sep 19 17:18:11.196572 2020] [wsgi:error] [pid 23485] [remote 91.12.161.88:39034]     application = get_wsgi_application()
[Sat Sep 19 17:18:11.196578 2020] [wsgi:error] [pid 23485] [remote 91.12.161.88:39034]   File "/home/mastergoal_project/tmp/venv/lib/python3.7/site-packages/django/core/wsgi.py", line 12, in get_wsgi_application
[Sat Sep 19 17:18:11.196583 2020] [wsgi:error] [pid 23485] [remote 91.12.161.88:39034]     django.setup(set_prefix=False)
[Sat Sep 19 17:18:11.196592 2020] [wsgi:error] [pid 23485] [remote 91.12.161.88:39034]   File "/home/mastergoal_project/tmp/venv/lib/python3.7/site-packages/django/__init__.py", line 19, in setup
[Sat Sep 19 17:18:11.196598 2020] [wsgi:error] [pid 23485] [remote 91.12.161.88:39034]     configure_logging(settings.LOGGING_CONFIG, settings.LOGGING)
[Sat Sep 19 17:18:11.196608 2020] [wsgi:error] [pid 23485] [remote 91.12.161.88:39034]   File "/home/mastergoal_project/tmp/venv/lib/python3.7/site-packages/django/utils/log.py", line 76, in configure_logging
[Sat Sep 19 17:18:11.196614 2020] [wsgi:error] [pid 23485] [remote 91.12.161.88:39034]     logging_config_func(logging_settings)
[Sat Sep 19 17:18:11.196620 2020] [wsgi:error] [pid 23485] [remote 91.12.161.88:39034]   File "/usr/lib/python3.7/logging/config.py", line 800, in dictConfig
[Sat Sep 19 17:18:11.196624 2020] [wsgi:error] [pid 23485] [remote 91.12.161.88:39034]     dictConfigClass(config).configure()
[Sat Sep 19 17:18:11.196629 2020] [wsgi:error] [pid 23485] [remote 91.12.161.88:39034]   File "/usr/lib/python3.7/logging/config.py", line 571, in configure
[Sat Sep 19 17:18:11.196633 2020] [wsgi:error] [pid 23485] [remote 91.12.161.88:39034]     '%r' % name) from e
[Sat Sep 19 17:18:11.196653 2020] [wsgi:error] [pid 23485] [remote 91.12.161.88:39034] ValueError: Unable to configure handler 'critical'
[Sat Sep 19 17:18:11.719162 2020] [wsgi:error] [pid 23485] [remote 91.12.161.88:39046] mod_wsgi (pid=23485): Failed to exec Python script file '/home/mastergoal_project/config/wsgi.py'.
[Sat Sep 19 17:18:11.719216 2020] [wsgi:error] [pid 23485] [remote 91.12.161.88:39046] mod_wsgi (pid=23485): Exception occurred processing WSGI script '/home/mastergoal_project/config/wsgi.py'.
[Sat Sep 19 17:18:11.719518 2020] [wsgi:error] [pid 23485] [remote 91.12.161.88:39046] Traceback (most recent call last):
[Sat Sep 19 17:18:11.719578 2020] [wsgi:error] [pid 23485] [remote 91.12.161.88:39046]   File "/usr/lib/python3.7/logging/config.py", line 563, in configure
[Sat Sep 19 17:18:11.719587 2020] [wsgi:error] [pid 23485] [remote 91.12.161.88:39046]     handler = self.configure_handler(handlers[name])
[Sat Sep 19 17:18:11.719595 2020] [wsgi:error] [pid 23485] [remote 91.12.161.88:39046]   File "/usr/lib/python3.7/logging/config.py", line 736, in configure_handler
[Sat Sep 19 17:18:11.719599 2020] [wsgi:error] [pid 23485] [remote 91.12.161.88:39046]     result = factory(**kwargs)
[Sat Sep 19 17:18:11.719605 2020] [wsgi:error] [pid 23485] [remote 91.12.161.88:39046]   File "/usr/lib/python3.7/logging/__init__.py", line 1087, in __init__
[Sat Sep 19 17:18:11.719609 2020] [wsgi:error] [pid 23485] [remote 91.12.161.88:39046]     StreamHandler.__init__(self, self._open())
[Sat Sep 19 17:18:11.719615 2020] [wsgi:error] [pid 23485] [remote 91.12.161.88:39046]   File "/usr/lib/python3.7/logging/__init__.py", line 1116, in _open
[Sat Sep 19 17:18:11.719619 2020] [wsgi:error] [pid 23485] [remote 91.12.161.88:39046]     return open(self.baseFilename, self.mode, encoding=self.encoding)
[Sat Sep 19 17:18:11.719633 2020] [wsgi:error] [pid 23485] [remote 91.12.161.88:39046] FileNotFoundError: [Errno 2] No such file or directory: '/home/mastergoal_project/logs/critical.log'
[Sat Sep 19 17:18:11.719642 2020] [wsgi:error] [pid 23485] [remote 91.12.161.88:39046] 
[Sat Sep 19 17:18:11.719646 2020] [wsgi:error] [pid 23485] [remote 91.12.161.88:39046] The above exception was the direct cause of the following exception:
[Sat Sep 19 17:18:11.719654 2020] [wsgi:error] [pid 23485] [remote 91.12.161.88:39046] 
[Sat Sep 19 17:18:11.719660 2020] [wsgi:error] [pid 23485] [remote 91.12.161.88:39046] Traceback (most recent call last):
[Sat Sep 19 17:18:11.719685 2020] [wsgi:error] [pid 23485] [remote 91.12.161.88:39046]   File "/home/mastergoal_project/config/wsgi.py", line 16, in <module>
[Sat Sep 19 17:18:11.719689 2020] [wsgi:error] [pid 23485] [remote 91.12.161.88:39046]     application = get_wsgi_application()
[Sat Sep 19 17:18:11.719695 2020] [wsgi:error] [pid 23485] [remote 91.12.161.88:39046]   File "/home/mastergoal_project/tmp/venv/lib/python3.7/site-packages/django/core/wsgi.py", line 12, in get_wsgi_application
[Sat Sep 19 17:18:11.719700 2020] [wsgi:error] [pid 23485] [remote 91.12.161.88:39046]     django.setup(set_prefix=False)
[Sat Sep 19 17:18:11.719705 2020] [wsgi:error] [pid 23485] [remote 91.12.161.88:39046]   File "/home/mastergoal_project/tmp/venv/lib/python3.7/site-packages/django/__init__.py", line 19, in setup
[Sat Sep 19 17:18:11.719709 2020] [wsgi:error] [pid 23485] [remote 91.12.161.88:39046]     configure_logging(settings.LOGGING_CONFIG, settings.LOGGING)
[Sat Sep 19 17:18:11.719715 2020] [wsgi:error] [pid 23485] [remote 91.12.161.88:39046]   File "/home/mastergoal_project/tmp/venv/lib/python3.7/site-packages/django/utils/log.py", line 76, in configure_logging
[Sat Sep 19 17:18:11.719719 2020] [wsgi:error] [pid 23485] [remote 91.12.161.88:39046]     logging_config_func(logging_settings)
[Sat Sep 19 17:18:11.719725 2020] [wsgi:error] [pid 23485] [remote 91.12.161.88:39046]   File "/usr/lib/python3.7/logging/config.py", line 800, in dictConfig
[Sat Sep 19 17:18:11.719729 2020] [wsgi:error] [pid 23485] [remote 91.12.161.88:39046]     dictConfigClass(config).configure()
[Sat Sep 19 17:18:11.719746 2020] [wsgi:error] [pid 23485] [remote 91.12.161.88:39046]   File "/usr/lib/python3.7/logging/config.py", line 571, in configure
[Sat Sep 19 17:18:11.719750 2020] [wsgi:error] [pid 23485] [remote 91.12.161.88:39046]     '%r' % name) from e
[Sat Sep 19 17:18:11.719760 2020] [wsgi:error] [pid 23485] [remote 91.12.161.88:39046] ValueError: Unable to configure handler 'critical'
