OK: /g/repetitivetodo/1535
Traceback (most recent call last):
  File "/home/mastergoal_project/m_env/lib/python3.6/site-packages/django/core/handlers/exception.py", line 34, in inner
    response = get_response(request)
  File "/home/mastergoal_project/m_env/lib/python3.6/site-packages/django/core/handlers/base.py", line 145, in _get_response
    response = self.process_exception_by_middleware(e, request)
  File "/home/mastergoal_project/m_env/lib/python3.6/site-packages/django/core/handlers/base.py", line 143, in _get_response
    response = response.render()
  File "/home/mastergoal_project/m_env/lib/python3.6/site-packages/django/template/response.py", line 106, in render
    self.content = self.rendered_content
  File "/home/mastergoal_project/m_env/lib/python3.6/site-packages/django/template/response.py", line 83, in rendered_content
    content = template.render(context, self._request)
  File "/home/mastergoal_project/m_env/lib/python3.6/site-packages/django/template/backends/jinja2.py", line 71, in render
    return self.template.render(context)
  File "/home/mastergoal_project/m_env/lib/python3.6/site-packages/jinja2/asyncsupport.py", line 76, in render
    return original_render(self, *args, **kwargs)
  File "/home/mastergoal_project/m_env/lib/python3.6/site-packages/jinja2/environment.py", line 1008, in render
    return self.environment.handle_exception(exc_info, True)
  File "/home/mastergoal_project/m_env/lib/python3.6/site-packages/jinja2/environment.py", line 780, in handle_exception
    reraise(exc_type, exc_value, tb)
  File "/home/mastergoal_project/m_env/lib/python3.6/site-packages/jinja2/_compat.py", line 37, in reraise
    raise value.with_traceback(tb)
  File "/home/mastergoal_project/mastergoal/mastergoal/templates/goals_to_do.j2", line 4, in top-level template code
    {% set title=to_do.name + " | To Do | Goals" %}
  File "/home/mastergoal_project/mastergoal/mastergoal/templates/layout/lhmf.j2", line 5, in top-level template code
    {% set z_index=1 %}
  File "/home/mastergoal_project/mastergoal/mastergoal/templates/layout/base.j2", line 38, in top-level template code
    {% block body %}
  File "/home/mastergoal_project/mastergoal/mastergoal/templates/layout/lhmf.j2", line 32, in block "body"
    {% block main %}{% endblock %}
  File "/home/mastergoal_project/mastergoal/mastergoal/templates/goals_to_do.j2", line 117, in block "main"
    Previous: {{ prev }} <a class="adminator-href-button" href="{{ url('goals:repetitive_to_do', args=[prev.pk]) }}">Open</a>
  File "/home/mastergoal_project/m_env/lib/python3.6/site-packages/django/urls/base.py", line 90, in reverse
    return iri_to_uri(resolver._reverse_with_prefix(view, prefix, *args, **kwargs))
  File "/home/mastergoal_project/m_env/lib/python3.6/site-packages/django/urls/resolvers.py", line 668, in _reverse_with_prefix
    raise NoReverseMatch(msg)
django.urls.exceptions.NoReverseMatch: Reverse for 'repetitive_to_do' with arguments '(Undefined,)' not found. 1 pattern(s) tried: ['g\\/repetitivetodo\\/(?P<pk>[^/]+)$']
OK: /g/repetitivetodo/1535
Traceback (most recent call last):
  File "/home/mastergoal_project/m_env/lib/python3.6/site-packages/django/core/handlers/exception.py", line 34, in inner
    response = get_response(request)
  File "/home/mastergoal_project/m_env/lib/python3.6/site-packages/django/core/handlers/base.py", line 145, in _get_response
    response = self.process_exception_by_middleware(e, request)
  File "/home/mastergoal_project/m_env/lib/python3.6/site-packages/django/core/handlers/base.py", line 143, in _get_response
    response = response.render()
  File "/home/mastergoal_project/m_env/lib/python3.6/site-packages/django/template/response.py", line 106, in render
    self.content = self.rendered_content
  File "/home/mastergoal_project/m_env/lib/python3.6/site-packages/django/template/response.py", line 83, in rendered_content
    content = template.render(context, self._request)
  File "/home/mastergoal_project/m_env/lib/python3.6/site-packages/django/template/backends/jinja2.py", line 71, in render
    return self.template.render(context)
  File "/home/mastergoal_project/m_env/lib/python3.6/site-packages/jinja2/asyncsupport.py", line 76, in render
    return original_render(self, *args, **kwargs)
  File "/home/mastergoal_project/m_env/lib/python3.6/site-packages/jinja2/environment.py", line 1008, in render
    return self.environment.handle_exception(exc_info, True)
  File "/home/mastergoal_project/m_env/lib/python3.6/site-packages/jinja2/environment.py", line 780, in handle_exception
    reraise(exc_type, exc_value, tb)
  File "/home/mastergoal_project/m_env/lib/python3.6/site-packages/jinja2/_compat.py", line 37, in reraise
    raise value.with_traceback(tb)
  File "/home/mastergoal_project/mastergoal/mastergoal/templates/goals_to_do.j2", line 4, in top-level template code
    {% set title=to_do.name + " | To Do | Goals" %}
  File "/home/mastergoal_project/mastergoal/mastergoal/templates/layout/lhmf.j2", line 5, in top-level template code
    {% set z_index=1 %}
  File "/home/mastergoal_project/mastergoal/mastergoal/templates/layout/base.j2", line 38, in top-level template code
    {% block body %}
  File "/home/mastergoal_project/mastergoal/mastergoal/templates/layout/lhmf.j2", line 32, in block "body"
    {% block main %}{% endblock %}
  File "/home/mastergoal_project/mastergoal/mastergoal/templates/goals_to_do.j2", line 117, in block "main"
    Previous: {{ prev }} <a class="adminator-href-button" href="{{ url('goals:repetitive_to_do', args=[prev.pk]) }}">Open</a>
  File "/home/mastergoal_project/m_env/lib/python3.6/site-packages/django/urls/base.py", line 90, in reverse
    return iri_to_uri(resolver._reverse_with_prefix(view, prefix, *args, **kwargs))
  File "/home/mastergoal_project/m_env/lib/python3.6/site-packages/django/urls/resolvers.py", line 668, in _reverse_with_prefix
    raise NoReverseMatch(msg)
django.urls.exceptions.NoReverseMatch: Reverse for 'repetitive_to_do' with arguments '(Undefined,)' not found. 1 pattern(s) tried: ['g\\/repetitivetodo\\/(?P<pk>[^/]+)$']
OK: /g/repetitivetodo/1507
Traceback (most recent call last):
  File "/home/mastergoal_project/m_env/lib/python3.6/site-packages/django/core/handlers/exception.py", line 34, in inner
    response = get_response(request)
  File "/home/mastergoal_project/m_env/lib/python3.6/site-packages/django/core/handlers/base.py", line 145, in _get_response
    response = self.process_exception_by_middleware(e, request)
  File "/home/mastergoal_project/m_env/lib/python3.6/site-packages/django/core/handlers/base.py", line 143, in _get_response
    response = response.render()
  File "/home/mastergoal_project/m_env/lib/python3.6/site-packages/django/template/response.py", line 106, in render
    self.content = self.rendered_content
  File "/home/mastergoal_project/m_env/lib/python3.6/site-packages/django/template/response.py", line 83, in rendered_content
    content = template.render(context, self._request)
  File "/home/mastergoal_project/m_env/lib/python3.6/site-packages/django/template/backends/jinja2.py", line 71, in render
    return self.template.render(context)
  File "/home/mastergoal_project/m_env/lib/python3.6/site-packages/jinja2/asyncsupport.py", line 76, in render
    return original_render(self, *args, **kwargs)
  File "/home/mastergoal_project/m_env/lib/python3.6/site-packages/jinja2/environment.py", line 1008, in render
    return self.environment.handle_exception(exc_info, True)
  File "/home/mastergoal_project/m_env/lib/python3.6/site-packages/jinja2/environment.py", line 780, in handle_exception
    reraise(exc_type, exc_value, tb)
  File "/home/mastergoal_project/m_env/lib/python3.6/site-packages/jinja2/_compat.py", line 37, in reraise
    raise value.with_traceback(tb)
  File "/home/mastergoal_project/mastergoal/mastergoal/templates/goals_to_do.j2", line 4, in top-level template code
    {% set title=to_do.name + " | To Do | Goals" %}
  File "/home/mastergoal_project/mastergoal/mastergoal/templates/layout/lhmf.j2", line 5, in top-level template code
    {% set z_index=1 %}
  File "/home/mastergoal_project/mastergoal/mastergoal/templates/layout/base.j2", line 38, in top-level template code
    {% block body %}
  File "/home/mastergoal_project/mastergoal/mastergoal/templates/layout/lhmf.j2", line 32, in block "body"
    {% block main %}{% endblock %}
  File "/home/mastergoal_project/mastergoal/mastergoal/templates/goals_to_do.j2", line 117, in block "main"
    Previous: {{ prev }} <a class="adminator-href-button" href="{{ url('goals:repetitive_to_do', args=[prev.pk]) }}">Open</a>
  File "/home/mastergoal_project/m_env/lib/python3.6/site-packages/django/urls/base.py", line 90, in reverse
    return iri_to_uri(resolver._reverse_with_prefix(view, prefix, *args, **kwargs))
  File "/home/mastergoal_project/m_env/lib/python3.6/site-packages/django/urls/resolvers.py", line 668, in _reverse_with_prefix
    raise NoReverseMatch(msg)
django.urls.exceptions.NoReverseMatch: Reverse for 'repetitive_to_do' with arguments '(Undefined,)' not found. 1 pattern(s) tried: ['g\\/repetitivetodo\\/(?P<pk>[^/]+)$']
OK: /g/repetitivetodo/1535
Traceback (most recent call last):
  File "/home/mastergoal_project/m_env/lib/python3.6/site-packages/django/core/handlers/exception.py", line 34, in inner
    response = get_response(request)
  File "/home/mastergoal_project/m_env/lib/python3.6/site-packages/django/core/handlers/base.py", line 145, in _get_response
    response = self.process_exception_by_middleware(e, request)
  File "/home/mastergoal_project/m_env/lib/python3.6/site-packages/django/core/handlers/base.py", line 143, in _get_response
    response = response.render()
  File "/home/mastergoal_project/m_env/lib/python3.6/site-packages/django/template/response.py", line 106, in render
    self.content = self.rendered_content
  File "/home/mastergoal_project/m_env/lib/python3.6/site-packages/django/template/response.py", line 83, in rendered_content
    content = template.render(context, self._request)
  File "/home/mastergoal_project/m_env/lib/python3.6/site-packages/django/template/backends/jinja2.py", line 71, in render
    return self.template.render(context)
  File "/home/mastergoal_project/m_env/lib/python3.6/site-packages/jinja2/asyncsupport.py", line 76, in render
    return original_render(self, *args, **kwargs)
  File "/home/mastergoal_project/m_env/lib/python3.6/site-packages/jinja2/environment.py", line 1008, in render
    return self.environment.handle_exception(exc_info, True)
  File "/home/mastergoal_project/m_env/lib/python3.6/site-packages/jinja2/environment.py", line 780, in handle_exception
    reraise(exc_type, exc_value, tb)
  File "/home/mastergoal_project/m_env/lib/python3.6/site-packages/jinja2/_compat.py", line 37, in reraise
    raise value.with_traceback(tb)
  File "/home/mastergoal_project/mastergoal/mastergoal/templates/goals_to_do.j2", line 4, in top-level template code
    {% set title=to_do.name + " | To Do | Goals" %}
  File "/home/mastergoal_project/mastergoal/mastergoal/templates/layout/lhmf.j2", line 5, in top-level template code
    {% set z_index=1 %}
  File "/home/mastergoal_project/mastergoal/mastergoal/templates/layout/base.j2", line 38, in top-level template code
    {% block body %}
  File "/home/mastergoal_project/mastergoal/mastergoal/templates/layout/lhmf.j2", line 32, in block "body"
    {% block main %}{% endblock %}
  File "/home/mastergoal_project/mastergoal/mastergoal/templates/goals_to_do.j2", line 117, in block "main"
    Previous: {{ prev }} <a class="adminator-href-button" href="{{ url('goals:repetitive_to_do', args=[prev.pk]) }}">Open</a>
  File "/home/mastergoal_project/m_env/lib/python3.6/site-packages/django/urls/base.py", line 90, in reverse
    return iri_to_uri(resolver._reverse_with_prefix(view, prefix, *args, **kwargs))
  File "/home/mastergoal_project/m_env/lib/python3.6/site-packages/django/urls/resolvers.py", line 668, in _reverse_with_prefix
    raise NoReverseMatch(msg)
django.urls.exceptions.NoReverseMatch: Reverse for 'repetitive_to_do' with arguments '(Undefined,)' not found. 1 pattern(s) tried: ['g\\/repetitivetodo\\/(?P<pk>[^/]+)$']
OK: /g/repetitivetodo/1507
Traceback (most recent call last):
  File "/home/mastergoal_project/m_env/lib/python3.6/site-packages/django/core/handlers/exception.py", line 34, in inner
    response = get_response(request)
  File "/home/mastergoal_project/m_env/lib/python3.6/site-packages/django/core/handlers/base.py", line 145, in _get_response
    response = self.process_exception_by_middleware(e, request)
  File "/home/mastergoal_project/m_env/lib/python3.6/site-packages/django/core/handlers/base.py", line 143, in _get_response
    response = response.render()
  File "/home/mastergoal_project/m_env/lib/python3.6/site-packages/django/template/response.py", line 106, in render
    self.content = self.rendered_content
  File "/home/mastergoal_project/m_env/lib/python3.6/site-packages/django/template/response.py", line 83, in rendered_content
    content = template.render(context, self._request)
  File "/home/mastergoal_project/m_env/lib/python3.6/site-packages/django/template/backends/jinja2.py", line 71, in render
    return self.template.render(context)
  File "/home/mastergoal_project/m_env/lib/python3.6/site-packages/jinja2/asyncsupport.py", line 76, in render
    return original_render(self, *args, **kwargs)
  File "/home/mastergoal_project/m_env/lib/python3.6/site-packages/jinja2/environment.py", line 1008, in render
    return self.environment.handle_exception(exc_info, True)
  File "/home/mastergoal_project/m_env/lib/python3.6/site-packages/jinja2/environment.py", line 780, in handle_exception
    reraise(exc_type, exc_value, tb)
  File "/home/mastergoal_project/m_env/lib/python3.6/site-packages/jinja2/_compat.py", line 37, in reraise
    raise value.with_traceback(tb)
  File "/home/mastergoal_project/mastergoal/mastergoal/templates/goals_to_do.j2", line 4, in top-level template code
    {% set title=to_do.name + " | To Do | Goals" %}
  File "/home/mastergoal_project/mastergoal/mastergoal/templates/layout/lhmf.j2", line 5, in top-level template code
    {% set z_index=1 %}
  File "/home/mastergoal_project/mastergoal/mastergoal/templates/layout/base.j2", line 38, in top-level template code
    {% block body %}
  File "/home/mastergoal_project/mastergoal/mastergoal/templates/layout/lhmf.j2", line 32, in block "body"
    {% block main %}{% endblock %}
  File "/home/mastergoal_project/mastergoal/mastergoal/templates/goals_to_do.j2", line 117, in block "main"
    Previous: {{ prev }} <a class="adminator-href-button" href="{{ url('goals:repetitive_to_do', args=[prev.pk]) }}">Open</a>
  File "/home/mastergoal_project/m_env/lib/python3.6/site-packages/django/urls/base.py", line 90, in reverse
    return iri_to_uri(resolver._reverse_with_prefix(view, prefix, *args, **kwargs))
  File "/home/mastergoal_project/m_env/lib/python3.6/site-packages/django/urls/resolvers.py", line 668, in _reverse_with_prefix
    raise NoReverseMatch(msg)
django.urls.exceptions.NoReverseMatch: Reverse for 'repetitive_to_do' with arguments '(Undefined,)' not found. 1 pattern(s) tried: ['g\\/repetitivetodo\\/(?P<pk>[^/]+)$']
OK: /g/repetitivetodo/1538
Traceback (most recent call last):
  File "/home/mastergoal_project/m_env/lib/python3.6/site-packages/django/core/handlers/exception.py", line 34, in inner
    response = get_response(request)
  File "/home/mastergoal_project/m_env/lib/python3.6/site-packages/django/core/handlers/base.py", line 145, in _get_response
    response = self.process_exception_by_middleware(e, request)
  File "/home/mastergoal_project/m_env/lib/python3.6/site-packages/django/core/handlers/base.py", line 143, in _get_response
    response = response.render()
  File "/home/mastergoal_project/m_env/lib/python3.6/site-packages/django/template/response.py", line 106, in render
    self.content = self.rendered_content
  File "/home/mastergoal_project/m_env/lib/python3.6/site-packages/django/template/response.py", line 83, in rendered_content
    content = template.render(context, self._request)
  File "/home/mastergoal_project/m_env/lib/python3.6/site-packages/django/template/backends/jinja2.py", line 71, in render
    return self.template.render(context)
  File "/home/mastergoal_project/m_env/lib/python3.6/site-packages/jinja2/asyncsupport.py", line 76, in render
    return original_render(self, *args, **kwargs)
  File "/home/mastergoal_project/m_env/lib/python3.6/site-packages/jinja2/environment.py", line 1008, in render
    return self.environment.handle_exception(exc_info, True)
  File "/home/mastergoal_project/m_env/lib/python3.6/site-packages/jinja2/environment.py", line 780, in handle_exception
    reraise(exc_type, exc_value, tb)
  File "/home/mastergoal_project/m_env/lib/python3.6/site-packages/jinja2/_compat.py", line 37, in reraise
    raise value.with_traceback(tb)
  File "/home/mastergoal_project/mastergoal/mastergoal/templates/goals_to_do.j2", line 4, in top-level template code
    {% set title=to_do.name + " | To Do | Goals" %}
  File "/home/mastergoal_project/mastergoal/mastergoal/templates/layout/lhmf.j2", line 5, in top-level template code
    {% set z_index=1 %}
  File "/home/mastergoal_project/mastergoal/mastergoal/templates/layout/base.j2", line 38, in top-level template code
    {% block body %}
  File "/home/mastergoal_project/mastergoal/mastergoal/templates/layout/lhmf.j2", line 32, in block "body"
    {% block main %}{% endblock %}
  File "/home/mastergoal_project/mastergoal/mastergoal/templates/goals_to_do.j2", line 117, in block "main"
    Previous: {{ prev }} <a class="adminator-href-button" href="{{ url('goals:repetitive_to_do', args=[prev.pk]) }}">Open</a>
  File "/home/mastergoal_project/m_env/lib/python3.6/site-packages/django/urls/base.py", line 90, in reverse
    return iri_to_uri(resolver._reverse_with_prefix(view, prefix, *args, **kwargs))
  File "/home/mastergoal_project/m_env/lib/python3.6/site-packages/django/urls/resolvers.py", line 668, in _reverse_with_prefix
    raise NoReverseMatch(msg)
django.urls.exceptions.NoReverseMatch: Reverse for 'repetitive_to_do' with arguments '(Undefined,)' not found. 1 pattern(s) tried: ['g\\/repetitivetodo\\/(?P<pk>[^/]+)$']
